Workbook

Sheet Invoice_Courier Company
A1: AWB Code | B1: Order ID | C1: Charged Weight | D1: Warehouse Pincode | E1: Customer Pincode | F1: Zone | G1: Type of Shipment | H1: Billing Amount (Rs.)
A2: 1091117222124 | B2: 2001806232 | C2: 1.3 | D2: 121003 | E2: 507101 | F2: d | G2: Forward charges | H2: 135
A3: 1091117222194 | B3: 2001806273 | C3: 1 | D3: 121003 | E3: 486886 | F3: d | G3: Forward charges | H3: 90.2
A4: 1091117222931 | B4: 2001806408 | C4: 2.5 | D4: 121003 | E4: 532484 | F4: d | G4: Forward charges | H4: 224.6
A5: 1091117223244 | B5: 2001806458 | C5: 1 | D5: 121003 | E5: 143001 | F5: b | G5: Forward charges | H5: 61.3
A6: 1091117229345 | B6: 2001807012 | C6: 0.15 | D6: 121003 | E6: 515591 | F6: d | G6: Forward charges | H6: 45.4
A7: 1091117229555 | B7: 2001806686 | C7: 0.15 | D7: 121003 | E7: 326502 | F7: d | G7: Forward charges | H7: 45.4
A8: 1091117229776 | B8: 2001806885 | C8: 1 | D8: 121003 | E8: 208019 | F8: b | G8: Forward charges | H8: 61.3
A9: 1091117323112 | B9: 2001807058 | C9: 1.15 | D9: 121003 | E9: 140301 | F9: b | G9: Forward charges | H9: 89.6
A10: 1091117323812 | B10: 2001807186 | C10: 0.5 | D10: 121003 | E10: 396001 | F10: d | G10: Forward charges | H10: 45.4
A11: 1091117324206 | B11: 2001807290 | C11: 0.5 | D11: 121003 | E11: 711106 | F11: d | G11: Forward charges | H11: 45.4
A12: 1091117326612 | B12: 2001807814 | C12: 0.79 | D12: 121003 | E12: 284001 | F12: b | G12: Forward charges | H12: 61.3
A13: 1091117327172 | B13: 2001807931 | C13: 0.72 | D13: 121003 | E13: 441601 | F13: d | G13: Forward charges | H13: 90.2
... A125: 1091121846136 | B125: 2001811305 | C125: 0.5 | D125: 121003 | E125: 302020 | F125: d | G125: Forward charges | H125: 45.4

Sheet SKU_Company
A1: SKU | B1: Weight (g)
A2: 8904223815682 | B2: 210
A3: 8904223815859 | B3: 165
A4: 8904223815866 | B4: 113
A5: 8904223815873 | B5: 65
A6: 8904223816214 | B6: 120
A7: 8904223816665 | B7: 102
A8: 8904223817273 | B8: 65
A9: 8904223817334 | B9: 170
A10: 8904223817501 | B10: 350
A11: 8904223818430 | B11: 165
A12: 8904223818478 | B12: 350
A13: 8904223818553 | B13: 115
... A51: 8904223819437 | B51: 552
A52: GIFTBOX202001 | B52: 500
A53: GIFTBOX202004 | B53: 500
A54: GIFTBOX202002 | B54: 500
A55: 8904223819369 | B55: 170
A56: GIFTBOX202003 | B56: 500
A57: 8904223819123 | B57: 250
A58: GIFTBOX202002 | B58: 500
A59: 8904223819468 | B59: 240
A60: 8904223819260 | B60: 130
A61: 8904223819321 | B61: 600
A62: 8904223819338 | B62: 600
A63: 8904223819505 | B63: 210
A64: 8904223819499 | B64: 210
A65: 8904223819512 | B65: 210
A66: 8904223819543 | B66: 300
A67: SACHETS001 | B67: 10

Sheet Rates_Courier Company
A1: fwd_a_fixed | B1: fwd_a_additional | C1: fwd_b_fixed | D1: fwd_b_additional | E1: fwd_c_fixed | F1: fwd_c_additional | G1: fwd_d_fixed | H1: fwd_d_additional | I1: fwd_e_fixed | J1: fwd_e_additional | K1: rto_a_fixed | L1: rto_a_additional | M1: rto_b_fixed | N1: rto_b_additional | O1: rto_c_fixed | P1: rto_c_additional | Q1: rto_d_fixed | R1: rto_d_additional | S1: rto_e_fixed | T1: rto_e_additional
A2: 29.5 | B2: 23.6 | C2: 33 | D2: 28.3 | E2: 40.1 | F2: 38.9 | G2: 45.4 | H2: 44.8 | I2: 56.6 | J2: 55.5 | K2: 13.6 | L2: 23.6 | M2: 20.5 | N2: 28.3 | O2: 31.9 | P2: 38.9 | Q2: 41.3 | R2: 44.8 | S2: 50.7 | T2: 55.5
B7: Zone | C7: Fwd_Fixed | F7: Zone | G7: RTO_Fixed
B8: A | C8: 29.5 | F8: A | G8: 13.6
B9: B | C9: 33 | F9: B | G9: 20.5
B10: C | C10: 40.1 | F10: C | G10: 31.9
B11: D | C11: 45.4 | F11: D | G11: 41.3
B12: E | C12: 56.6 | F12: E | G12: 50.7
B15: Zone | C15: Fwd_Additional | F15: Zone | G15: RTO_Additional
B16: A | C16: 23.6 | F16: A | G16: 23.6
B17: B | C17: 28.3 | F17: B | G17: 28.3
B18: C | C18: 38.9 | F18: C | G18: 38.9
B19: D | C19: 44.8 | F19: D | G19: 44.8
B20: E | C20: 55.5 | F20: E | G20: 55.5

Sheet Zones Pincode_Company X
A1: Warehouse Pincode | B1: Customer Pincode | C1: Zone
A2: 121003 | B2: 507101 | C2: d
A3: 121003 | B3: 486886 | C3: d
A4: 121003 | B4: 532484 | C4: d
A5: 121003 | B5: 143001 | C5: b
A6: 121003 | B6: 515591 | C6: d
A7: 121003 | B7: 326502 | C7: d
A8: 121003 | B8: 208019 | C8: b
A9: 121003 | B9: 140301 | C9: b
A10: 121003 | B10: 396001 | C10: d
A11: 121003 | B11: 711106 | C11: d
A12: 121003 | B12: 284001 | C12: b
A13: 121003 | B13: 441601 | C13: d
... A125: 121003 | B125: 302020 | C125: b

Sheet Order Report_Company X
A1: ExternOrderNo | B1: SKU | C1: Order Qty | D1: Weight_Gm | E1: Total_Weight_Gm
A2: 2001827036 | B2: 8904223818706 | C2: 1 | D2: =VLOOKUP(B2,SKU_Company!A:B,2,FALSE) -> 127 | E2: =D2*C2 -> 127
A3: 2001827036 | B3: 8904223819093 | C3: 1 | D3: =VLOOKUP(B3,SKU_Company!A:B,2,FALSE) -> 150 | E3: =D3*C3 -> 150
A4: 2001827036 | B4: 8904223819109 | C4: 1 | D4: =VLOOKUP(B4,SKU_Company!A:B,2,FALSE) -> 100 | E4: =D4*C4 -> 100
A5: 2001827036 | B5: 8904223818430 | C5: 1 | D5: =VLOOKUP(B5,SKU_Company!A:B,2,FALSE) -> 165 | E5: =D5*C5 -> 165
A6: 2001827036 | B6: 8904223819277 | C6: 1 | D6: =VLOOKUP(B6,SKU_Company!A:B,2,FALSE) -> 350 | E6: =D6*C6 -> 350
A7: 2001827036 | B7: GIFTBOX202002 | C7: 1 | D7: =VLOOKUP(B7,SKU_Company!A:B,2,FALSE) -> 500 | E7: =D7*C7 -> 500
A8: 2001827036 | B8: 8904223818638 | C8: 2 | D8: =VLOOKUP(B8,SKU_Company!A:B,2,FALSE) -> 137 | E8: =D8*C8 -> 274
A9: 2001827036 | B9: SACHETS001 | C9: 1 | D9: =VLOOKUP(B9,SKU_Company!A:B,2,FALSE) -> 10 | E9: =D9*C9 -> 10
A10: 2001825261 | B10: 8904223819024 | C10: 4 | D10: =VLOOKUP(B10,SKU_Company!A:B,2,FALSE) -> 112 | E10: =D10*C10 -> 448
A11: 2001825261 | B11: 8904223819291 | C11: 4 | D11: =VLOOKUP(B11,SKU_Company!A:B,2,FALSE) -> 112 | E11: =D11*C11 -> 448
A12: 2001825261 | B12: 8904223818638 | C12: 3 | D12: =VLOOKUP(B12,SKU_Company!A:B,2,FALSE) -> 137 | E12: =D12*C12 -> 411
A13: 2001825261 | B13: 8904223818669 | C13: 1 | D13: =VLOOKUP(B13,SKU_Company!A:B,2,FALSE) -> 240 | E13: =D13*C13 -> 240
A14: 2001825261 | B14: SACHETS001 | C14: 1 | D14: =VLOOKUP(B14,SKU_Company!A:B,2,FALSE) -> 10 | E14: =D14*C14 -> 10
A15: 2001823564 | B15: 8904223819291 | C15: 2 | D15: =VLOOKUP(B15,SKU_Company!A:B,2,FALSE) -> 112 | E15: =D15*C15 -> 224
A16: 2001823564 | B16: 8904223819031 | C16: 2 | D16: =VLOOKUP(B16,SKU_Company!A:B,2,FALSE) -> 112 | E16: =D16*C16 -> 224
A17: 2001823564 | B17: 8904223819024 | C17: 2 | D17: =VLOOKUP(B17,SKU_Company!A:B,2,FALSE) -> 112 | E17: =D17*C17 -> 224
A18: 2001822466 | B18: 8904223819468 | C18: 2 | D18: =VLOOKUP(B18,SKU_Company!A:B,2,FALSE) -> 240 | E18: =D18*C18 -> 480
A19: 2001822466 | B19: 8904223819291 | C19: 8 | D19: =VLOOKUP(B19,SKU_Company!A:B,2,FALSE) -> 112 | E19: =D19*C19 -> 896
A20: 2001821995 | B20: 8904223819130 | C20: 1 | D20: =VLOOKUP(B20,SKU_Company!A:B,2,FALSE) -> 350 | E20: =D20*C20 -> 350
A21: 2001821995 | B21: 8904223818706 | C21: 1 | D21: =VLOOKUP(B21,SKU_Company!A:B,2,FALSE) -> 127 | E21: =D21*C21 -> 127
A22: 2001821766 | B22: 8904223818591 | C22: 2 | D22: =VLOOKUP(B22,SKU_Company!A:B,2,FALSE) -> 120 | E22: =D22*C22 -> 240
A23: 2001821750 | B23: 8904223818850 | C23: 1 | D23: =VLOOKUP(B23,SKU_Company!A:B,2,FALSE) -> 240 | E23: =D23*C23 -> 240
A24: 2001821750 | B24: 8904223818430 | C24: 1 | D24: =VLOOKUP(B24,SKU_Company!A:B,2,FALSE) -> 165 | E24: =D24*C24 -> 165
A25: 2001821750 | B25: 8904223819130 | C25: 1 | D25: =VLOOKUP(B25,SKU_Company!A:B,2,FALSE) -> 350 | E25: =D25*C25 -> 350
A26: 2001821742 | B26: 8904223819468 | C26: 1 | D26: =VLOOKUP(B26,SKU_Company!A:B,2,FALSE) -> 240 | E26: =D26*C26 -> 240
... A47: 2001819252 | B47: 8904223818706 | C47: 1 | D47: =VLOOKUP(B47,SKU_Company!A:B,2,FALSE) -> 127 | E47: =D47*C47 -> 127
A48: 2001819252 | B48: SACHETS001 | C48: 1 | D48: =VLOOKUP(B48,SKU_Company!A:B,2,FALSE) -> 10 | E48: =D48*C48 -> 10
A49: 2001818390 | B49: 8904223819147 | C49: 1 | D49: =VLOOKUP(B49,SKU_Company!A:B,2,FALSE) -> 240 | E49: =D49*C49 -> 240
A50: 2001818390 | B50: 8904223818935 | C50: 4 | D50: =VLOOKUP(B50,SKU_Company!A:B,2,FALSE) -> 120 | E50: =D50*C50 -> 480
A51: 2001818390 | B51: 8904223818683 | C51: 1 | D51: =VLOOKUP(B51,SKU_Company!A:B,2,FALSE) -> 121 | E51: =D51*C51 -> 121
A52: 2001817160 | B52: 8904223818478 | C52: 1 | D52: =VLOOKUP(B52,SKU_Company!A:B,2,FALSE) -> 350 | E52: =D52*C52 -> 350
A53: 2001817160 | B53: 8904223819284 | C53: 1 | D53: =VLOOKUP(B53,SKU_Company!A:B,2,FALSE) -> 350 | E53: =D53*C53 -> 350
A54: 2001817093 | B54: 8904223816214 | C54: 1 | D54: =VLOOKUP(B54,SKU_Company!A:B,2,FALSE) -> 120 | E54: =D54*C54 -> 120
A55: 2001817093 | B55: 8904223818874 | C55: 1 | D55: =VLOOKUP(B55,SKU_Company!A:B,2,FALSE) -> 100 | E55: =D55*C55 -> 100
A56: 2001817093 | B56: 8904223819512 | C56: 1 | D56: =VLOOKUP(B56,SKU_Company!A:B,2,FALSE) -> 210 | E56: =D56*C56 -> 210
A57: 2001817093 | B57: 8904223818881 | C57: 1 | D57: =VLOOKUP(B57,SKU_Company!A:B,2,FALSE) -> 140 | E57: =D57*C57 -> 140
A58: 2001817093 | B58: 8904223819291 | C58: 2 | D58: =VLOOKUP(B58,SKU_Company!A:B,2,FALSE) -> 112 | E58: =D58*C58 -> 224
A59: 2001817093 | B59: 8904223819031 | C59: 2 | D59: =VLOOKUP(B59,SKU_Company!A:B,2,FALSE) -> 112 | E59: =D59*C59 -> 224
A60: 2001817093 | B60: 8904223819024 | C60: 2 | D60: =VLOOKUP(B60,SKU_Company!A:B,2,FALSE) -> 112 | E60: =D60*C60 -> 224
...

Sheet Total Calculations_Company
A1: Order ID | B1: AWB Number | C1: Total weight as per X (KG) | D1: Weight slab as per X (KG) | E1: Total weight as per Courier Company (KG) | F1: Weight slab charged by Courier Company (KG) | G1: Delivery Zone as per X | H1: Delivery Zone charged by Courier Company | I1: Expected Charge as per X (Rs.) | J1: Charges Billed by Courier Company (Rs.) | K1: Difference Between Expected Charges and Billed Charges (Rs.)
A2: 2001806232 | B2: 1091117222124 | C2: 1.3 | D2: 1.5 | E2: 1.3 | F2: 1.5 | G2: D | H2: D | I2: 135 | J2: 135 | K2: 0
A3: 2001806210 | B3: 1091117221940 | C3: 0.22 | D3: 0.5 | E3: 2.92 | F3: 3 | G3: B | H3: B | I3: 33 | J3: 174.5 | K3: -141.5

Sheet Summary Table_Company
B6: Count | C6: Amount
A7: Total Orders - Correctly Charged | B7: =COUNTIF('Order Level Calculation_Company'!U:U,"=0") -> 22 | C7: =SUMIF('Order Level Calculation_Company'!U:U,"=0",'Order Level Calculation_Company'!P:P) -> 1826.9
A8: Total Orders - Over Charged | B8: =COUNTIF('Order Level Calculation_Company'!U:U,"<0") -> 79 | C8: =SUMIF('Order Level Calculation_Company'!U:U,"<0",'Order Level Calculation_Company'!U:U) -> -4426.6
A9: Total Orders - Under Charged | B9: =COUNTIF('Order Level Calculation_Company'!U:U,">0") -> 23 | C9: =SUMIF('Order Level Calculation_Company'!U:U,">0",'Order Level Calculation_Company'!U:U) -> 575.1

Sheet Order Level Calculation_Company
A1: OrderNo | B1: AWB Code | C1: Customer Pincode | D1: Type of Shipment | E1: Forward Charges Applicable | F1: RTO Charges Applicable | G1: Total weight as per X (KG) | H1: Total weight as per X (G) | I1: Weight slab as per X (KG) | J1: Weight slab as per X (G) | K1: Delivery zone as per X | L1: Forward_fixed _charges(X) | M1: Forward_additional_charges(X) | N1: RTO_Fixed_Charges(X) | O1: RTO_additional_Charges(X) | P1: Expected_charge as per X (Rs) | Q1: Total weight as per Courier Company (KG) | R1: Weight slab charged by Courier Company (KG) | S1: Delivery Zone charged by Courier Company | T1: Charges Billed by Courier Company (Rs.) | U1: Difference Between Expected Charges and Billed Charges (Rs.) | V1: Discount Applied (%) | W1: Net Forward Charges per KG (Rs./KG) | X1: Net RTO Charges per KG (Rs./KG)
A2: 2001806232 | B2: 1091117222124 | C2: =VLOOKUP(A2,'Invoice_Courier Company'!B:E,4,FALSE) -> 507101 | D2: =VLOOKUP(A2,'Invoice_Courier Company'!B:G,6,FALSE) -> Forward charges | E2: Yes | F2: =IF(D2="Forward and RTO charges","Yes","No") -> No | G2: =SUMIFS('Order Report_Company X'!E:E,'Order Report_Company X'!A:A,A2)/1000 -> 1.302 | H2: =SUMIFS('Order Report_Company X'!E:E,'Order Report_Company X'!A:A,'Order Level Calculation_Company'!A2) -> 1302 | I2: {=_xlfn.IFS($G2<=0.5,0.5,$G2<=1,1,$G2<=1.5,1.5,$G2<=2,2,$G2<=2.5,2.5,$G2<=3,3,$G2<=3.5,3.5,$G2<=4,4)} -> 1.5 | J2: {=_xlfn.IFS($H2<=500,0.5,$H2<=1000,1,$H2<=1500,1.5,$H2<=2000,2,$H2<=2500,2.5,$H2<=3000,3,$H2<=3500,3.5,$H2<=4000,4)*1000} -> 1500 | K2: =UPPER(VLOOKUP(C2,'Zones Pincode_Company X'!B:C,2,FALSE)) -> D | L2: =VLOOKUP(K2,'Rates_Courier Company'!$B$7:$C$12,2,0) -> 45.4 | M2: =VLOOKUP(K2,'Rates_Courier Company'!$B$15:$C$20,2,FALSE)*(I2/0.5-1) -> 89.6 | N2: =IF(F2="Yes",VLOOKUP(K2,'Rates_Courier Company'!$F$7:$G$12,2,0),0) -> 0 | O2: =IF(F2="Yes",VLOOKUP(K2,'Rates_Courier Company'!$F$15:$G$20,2,0),0)*(I2/0.5 -1) -> 0 | P2: =L2+M2+N2+O2 -> 135 | Q2: =VLOOKUP(A2,'Invoice_Courier Company'!B:C,2,0) -> 1.3 | R2: =IF(Q2<=0.5,0.5,IF(AND(Q2>0.5,Q2<=1),1,IF(AND(Q2>1,Q2<=1.5),1.5,IF(AND(Q2>1.5,Q2<=2),2,IF(AND(Q2>2,Q2<=2.5),2.5,3))))) -> 1.5 | S2: =UPPER(VLOOKUP(A2,'Invoice_Courier Company'!B:G,5,FALSE)) -> D | T2: =VLOOKUP(A2,'Invoice_Courier Company'!B:H,7,0) -> 135 | U2: =P2-T2 -> 0 | V2: =U2/P2 -> 0 | W2: =L2+M2 -> 135 | X2: =N2+O2 -> 0
A3: 2001806273 | B3: 1091117222194 | C3: =VLOOKUP(A3,'Invoice_Courier Company'!B:E,4,FALSE) -> 486886 | D3: =VLOOKUP(A3,'Invoice_Courier Company'!B:G,6,FALSE) -> Forward charges | E3: =IF(D3="Forward charges","Yes","No") -> Yes | F3: =IF(D3="Forward and RTO charges","Yes","No") -> No | G3: =SUMIFS('Order Report_Company X'!E:E,'Order Report_Company X'!A:A,A3)/1000 -> 0.615 | H3: =SUMIFS('Order Report_Company X'!E:E,'Order Report_Company X'!A:A,'Order Level Calculation_Company'!A3) -> 615 | I3: {=_xlfn.IFS($G3<=0.5,0.5,$G3<=1,1,$G3<=1.5,1.5,$G3<=2,2,$G3<=2.5,2.5,$G3<=3,3,$G3<=3.5,3.5,$G3<=4,4)} -> 1 | J3: {=_xlfn.IFS($H3<=500,0.5,$H3<=1000,1,$H3<=1500,1.5,$H3<=2000,2,$H3<=2500,2.5,$H3<=3000,3,$H3<=3500,3.5,$H3<=4000,4)*1000} -> 1000 | K3: =UPPER(VLOOKUP(C3,'Zones Pincode_Company X'!B:C,2,FALSE)) -> D | L3: =VLOOKUP(K3,'Rates_Courier Company'!$B$7:$C$12,2,0) -> 45.4 | M3: =VLOOKUP(K3,'Rates_Courier Company'!$B$15:$C$20,2,FALSE)*(I3/0.5-1) -> 44.8 | N3: =IF(F3="Yes",VLOOKUP(K3,'Rates_Courier Company'!$F$7:$G$12,2,0),0) -> 0 | O3: =IF(F3="Yes",VLOOKUP(K3,'Rates_Courier Company'!$F$15:$G$20,2,0),0)*(I3/0.5 -1) -> 0 | P3: =L3+M3+N3+O3 -> 90.2 | Q3: =VLOOKUP(A3,'Invoice_Courier Company'!B:C,2,0) -> 1 | R3: =IF(Q3<=0.5,0.5,IF(AND(Q3>0.5,Q3<=1),1,IF(AND(Q3>1,Q3<=1.5),1.5,IF(AND(Q3>1.5,Q3<=2),2,IF(AND(Q3>2,Q3<=2.5),2.5,3))))) -> 1 | S3: =UPPER(VLOOKUP(A3,'Invoice_Courier Company'!B:G,5,FALSE)) -> D | T3: =VLOOKUP(A3,'Invoice_Courier Company'!B:H,7,0) -> 90.2 | U3: =P3-T3 -> 0 | V3: =U3/P3 -> 0 | W3: =L3+M3 -> 90.2 | X3: =N3+O3 -> 0
A4: 2001806408 | B4: 1091117222931 | C4: =VLOOKUP(A4,'Invoice_Courier Company'!B:E,4,FALSE) -> 532484 | D4: =VLOOKUP(A4,'Invoice_Courier Company'!B:G,6,FALSE) -> Forward charges | E4: =IF(D4="Forward charges","Yes","No") -> Yes | F4: =IF(D4="Forward and RTO charges","Yes","No") -> No | G4: =SUMIFS('Order Report_Company X'!E:E,'Order Report_Company X'!A:A,A4)/1000 -> 2.265 | H4: =SUMIFS('Order Report_Company X'!E:E,'Order Report_Company X'!A:A,'Order Level Calculation_Company'!A4) -> 2265 | I4: {=_xlfn.IFS($G4<=0.5,0.5,$G4<=1,1,$G4<=1.5,1.5,$G4<=2,2,$G4<=2.5,2.5,$G4<=3,3,$G4<=3.5,3.5,$G4<=4,4)} -> 2.5 | J4: {=_xlfn.IFS($H4<=500,0.5,$H4<=1000,1,$H4<=1500,1.5,$H4<=2000,2,$H4<=2500,2.5,$H4<=3000,3,$H4<=3500,3.5,$H4<=4000,4)*1000} -> 2500 | K4: =UPPER(VLOOKUP(C4,'Zones Pincode_Company X'!B:C,2,FALSE)) -> D | L4: =VLOOKUP(K4,'Rates_Courier Company'!$B$7:$C$12,2,0) -> 45.4 | M4: =VLOOKUP(K4,'Rates_Courier Company'!$B$15:$C$20,2,FALSE)*(I4/0.5-1) -> 179.2 | N4: =IF(F4="Yes",VLOOKUP(K4,'Rates_Courier Company'!$F$7:$G$12,2,0),0) -> 0 | O4: =IF(F4="Yes",VLOOKUP(K4,'Rates_Courier Company'!$F$15:$G$20,2,0),0)*(I4/0.5 -1) -> 0 | P4: =L4+M4+N4+O4 -> 224.6 | Q4: =VLOOKUP(A4,'Invoice_Courier Company'!B:C,2,0) -> 2.5 | R4: =IF(Q4<=0.5,0.5,IF(AND(Q4>0.5,Q4<=1),1,IF(AND(Q4>1,Q4<=1.5),1.5,IF(AND(Q4>1.5,Q4<=2),2,IF(AND(Q4>2,Q4<=2.5),2.5,3))))) -> 2.5 | S4: =UPPER(VLOOKUP(A4,'Invoice_Courier Company'!B:G,5,FALSE)) -> D | T4: =VLOOKUP(A4,'Invoice_Courier Company'!B:H,7,0) -> 224.6 | U4: =P4-T4 -> 0 | V4: =U4/P4 -> 0 | W4: =L4+M4 -> 224.6 | X4: =N4+O4 -> 0
A5: 2001806458 | B5: 1091117223244 | C5: =VLOOKUP(A5,'Invoice_Courier Company'!B:E,4,FALSE) -> 143001 | D5: =VLOOKUP(A5,'Invoice_Courier Company'!B:G,6,FALSE) -> Forward charges | E5: =IF(D5="Forward charges","Yes","No") -> Yes | F5: =IF(D5="Forward and RTO charges","Yes","No") -> No | G5: =SUMIFS('Order Report_Company X'!E:E,'Order Report_Company X'!A:A,A5)/1000 -> 0.7 | H5: =SUMIFS('Order Report_Company X'!E:E,'Order Report_Company X'!A:A,'Order Level Calculation_Company'!A5) -> 700 | I5: {=_xlfn.IFS($G5<=0.5,0.5,$G5<=1,1,$G5<=1.5,1.5,$G5<=2,2,$G5<=2.5,2.5,$G5<=3,3,$G5<=3.5,3.5,$G5<=4,4)} -> 1 | J5: {=_xlfn.IFS($H5<=500,0.5,$H5<=1000,1,$H5<=1500,1.5,$H5<=2000,2,$H5<=2500,2.5,$H5<=3000,3,$H5<=3500,3.5,$H5<=4000,4)*1000} -> 1000 | K5: =UPPER(VLOOKUP(C5,'Zones Pincode_Company X'!B:C,2,FALSE)) -> B | L5: =VLOOKUP(K5,'Rates_Courier Company'!$B$7:$C$12,2,0) -> 33 | M5: =VLOOKUP(K5,'Rates_Courier Company'!$B$15:$C$20,2,FALSE)*(I5/0.5-1) -> 28.3 | N5: =IF(F5="Yes",VLOOKUP(K5,'Rates_Courier Company'!$F$7:$G$12,2,0),0) -> 0 | O5: =IF(F5="Yes",VLOOKUP(K5,'Rates_Courier Company'!$F$15:$G$20,2,0),0)*(I5/0.5 -1) -> 0 | P5: =L5+M5+N5+O5 -> 61.3 | Q5: =VLOOKUP(A5,'Invoice_Courier Company'!B:C,2,0) -> 1 | R5: =IF(Q5<=0.5,0.5,IF(AND(Q5>0.5,Q5<=1),1,IF(AND(Q5>1,Q5<=1.5),1.5,IF(AND(Q5>1.5,Q5<=2),2,IF(AND(Q5>2,Q5<=2.5),2.5,3))))) -> 1 | S5: =UPPER(VLOOKUP(A5,'Invoice_Courier Company'!B:G,5,FALSE)) -> B | T5: =VLOOKUP(A5,'Invoice_Courier Company'!B:H,7,0) -> 61.3 | U5: =P5-T5 -> 0 | V5: =U5/P5 -> 0 | W5: =L5+M5 -> 61.3 | X5: =N5+O5 -> 0
A6: 2001807012 | B6: 1091117229345 | C6: =VLOOKUP(A6,'Invoice_Courier Company'!B:E,4,FALSE) -> 515591 | D6: =VLOOKUP(A6,'Invoice_Courier Company'!B:G,6,FALSE) -> Forward charges | E6: =IF(D6="Forward charges","Yes","No") -> Yes | F6: =IF(D6="Forward and RTO charges","Yes","No") -> No | G6: =SUMIFS('Order Report_Company X'!E:E,'Order Report_Company X'!A:A,A6)/1000 -> 0.24 | H6: =SUMIFS('Order Report_Company X'!E:E,'Order Report_Company X'!A:A,'Order Level Calculation_Company'!A6) -> 240 | I6: {=_xlfn.IFS($G6<=0.5,0.5,$G6<=1,1,$G6<=1.5,1.5,$G6<=2,2,$G6<=2.5,2.5,$G6<=3,3,$G6<=3.5,3.5,$G6<=4,4)} -> 0.5 | J6: {=_xlfn.IFS($H6<=500,0.5,$H6<=1000,1,$H6<=1500,1.5,$H6<=2000,2,$H6<=2500,2.5,$H6<=3000,3,$H6<=3500,3.5,$H6<=4000,4)*1000} -> 500 | K6: =UPPER(VLOOKUP(C6,'Zones Pincode_Company X'!B:C,2,FALSE)) -> D | L6: =VLOOKUP(K6,'Rates_Courier Company'!$B$7:$C$12,2,0) -> 45.4 | M6: =VLOOKUP(K6,'Rates_Courier Company'!$B$15:$C$20,2,FALSE)*(I6/0.5-1) -> 0 | N6: =IF(F6="Yes",VLOOKUP(K6,'Rates_Courier Company'!$F$7:$G$12,2,0),0) -> 0 | O6: =IF(F6="Yes",VLOOKUP(K6,'Rates_Courier Company'!$F$15:$G$20,2,0),0)*(I6/0.5 -1) -> 0 | P6: =L6+M6+N6+O6 -> 45.4 | Q6: =VLOOKUP(A6,'Invoice_Courier Company'!B:C,2,0) -> 0.15 | R6: =IF(Q6<=0.5,0.5,IF(AND(Q6>0.5,Q6<=1),1,IF(AND(Q6>1,Q6<=1.5),1.5,IF(AND(Q6>1.5,Q6<=2),2,IF(AND(Q6>2,Q6<=2.5),2.5,3))))) -> 0.5 | S6: =UPPER(VLOOKUP(A6,'Invoice_Courier Company'!B:G,5,FALSE)) -> D | T6: =VLOOKUP(A6,'Invoice_Courier Company'!B:H,7,0) -> 45.4 | U6: =P6-T6 -> 0 | V6: =U6/P6 -> 0 | W6: =L6+M6 -> 45.4 | X6: =N6+O6 -> 0
A7: 2001806686 | B7: 1091117229555 | C7: =VLOOKUP(A7,'Invoice_Courier Company'!B:E,4,FALSE) -> 326502 | D7: =VLOOKUP(A7,'Invoice_Courier Company'!B:G,6,FALSE) -> Forward charges | E7: =IF(D7="Forward charges","Yes","No") -> Yes | F7: =IF(D7="Forward and RTO charges","Yes","No") -> No | G7: =SUMIFS('Order Report_Company X'!E:E,'Order Report_Company X'!A:A,A7)/1000 -> 0.24 | H7: =SUMIFS('Order Report_Company X'!E:E,'Order Report_Company X'!A:A,'Order Level Calculation_Company'!A7) -> 240 | I7: {=_xlfn.IFS($G7<=0.5,0.5,$G7<=1,1,$G7<=1.5,1.5,$G7<=2,2,$G7<=2.5,2.5,$G7<=3,3,$G7<=3.5,3.5,$G7<=4,4)} -> 0.5 | J7: {=_xlfn.IFS($H7<=500,0.5,$H7<=1000,1,$H7<=1500,1.5,$H7<=2000,2,$H7<=2500,2.5,$H7<=3000,3,$H7<=3500,3.5,$H7<=4000,4)*1000} -> 500 | K7: =UPPER(VLOOKUP(C7,'Zones Pincode_Company X'!B:C,2,FALSE)) -> D | L7: =VLOOKUP(K7,'Rates_Courier Company'!$B$7:$C$12,2,0) -> 45.4 | M7: =VLOOKUP(K7,'Rates_Courier Company'!$B$15:$C$20,2,FALSE)*(I7/0.5-1) -> 0 | N7: =IF(F7="Yes",VLOOKUP(K7,'Rates_Courier Company'!$F$7:$G$12,2,0),0) -> 0 | O7: =IF(F7="Yes",VLOOKUP(K7,'Rates_Courier Company'!$F$15:$G$20,2,0),0)*(I7/0.5 -1) -> 0 | P7: =L7+M7+N7+O7 -> 45.4 | Q7: =VLOOKUP(A7,'Invoice_Courier Company'!B:C,2,0) -> 0.15 | R7: =IF(Q7<=0.5,0.5,IF(AND(Q7>0.5,Q7<=1),1,IF(AND(Q7>1,Q7<=1.5),1.5,IF(AND(Q7>1.5,Q7<=2),2,IF(AND(Q7>2,Q7<=2.5),2.5,3))))) -> 0.5 | S7: =UPPER(VLOOKUP(A7,'Invoice_Courier Company'!B:G,5,FALSE)) -> D | T7: =VLOOKUP(A7,'Invoice_Courier Company'!B:H,7,0) -> 45.4 | U7: =P7-T7 -> 0 | V7: =U7/P7 -> 0 | W7: =L7+M7 -> 45.4 | X7: =N7+O7 -> 0
A8: 2001806885 | B8: 1091117229776 | C8: =VLOOKUP(A8,'Invoice_Courier Company'!B:E,4,FALSE) -> 208019 | D8: =VLOOKUP(A8,'Invoice_Courier Company'!B:G,6,FALSE) -> Forward charges | E8: =IF(D8="Forward charges","Yes","No") -> Yes | F8: =IF(D8="Forward and RTO charges","Yes","No") -> No | G8: =SUMIFS('Order Report_Company X'!E:E,'Order Report_Company X'!A:A,A8)/1000 -> 0.84 | H8: =SUMIFS('Order Report_Company X'!E:E,'Order Report_Company X'!A:A,'Order Level Calculation_Company'!A8) -> 840 | I8: {=_xlfn.IFS($G8<=0.5,0.5,$G8<=1,1,$G8<=1.5,1.5,$G8<=2,2,$G8<=2.5,2.5,$G8<=3,3,$G8<=3.5,3.5,$G8<=4,4)} -> 1 | J8: {=_xlfn.IFS($H8<=500,0.5,$H8<=1000,1,$H8<=1500,1.5,$H8<=2000,2,$H8<=2500,2.5,$H8<=3000,3,$H8<=3500,3.5,$H8<=4000,4)*1000} -> 1000 | K8: =UPPER(VLOOKUP(C8,'Zones Pincode_Company X'!B:C,2,FALSE)) -> B | L8: =VLOOKUP(K8,'Rates_Courier Company'!$B$7:$C$12,2,0) -> 33 | M8: =VLOOKUP(K8,'Rates_Courier Company'!$B$15:$C$20,2,FALSE)*(I8/0.5-1) -> 28.3 | N8: =IF(F8="Yes",VLOOKUP(K8,'Rates_Courier Company'!$F$7:$G$12,2,0),0) -> 0 | O8: =IF(F8="Yes",VLOOKUP(K8,'Rates_Courier Company'!$F$15:$G$20,2,0),0)*(I8/0.5 -1) -> 0 | P8: =L8+M8+N8+O8 -> 61.3 | Q8: =VLOOKUP(A8,'Invoice_Courier Company'!B:C,2,0) -> 1 | R8: =IF(Q8<=0.5,0.5,IF(AND(Q8>0.5,Q8<=1),1,IF(AND(Q8>1,Q8<=1.5),1.5,IF(AND(Q8>1.5,Q8<=2),2,IF(AND(Q8>2,Q8<=2.5),2.5,3))))) -> 1 | S8: =UPPER(VLOOKUP(A8,'Invoice_Courier Company'!B:G,5,FALSE)) -> B | T8: =VLOOKUP(A8,'Invoice_Courier Company'!B:H,7,0) -> 61.3 | U8: =P8-T8 -> 0 | V8: =U8/P8 -> 0 | W8: =L8+M8 -> 61.3 | X8: =N8+O8 -> 0
A9: 2001807058 | B9: 1091117323112 | C9: =VLOOKUP(A9,'Invoice_Courier Company'!B:E,4,FALSE) -> 140301 | D9: =VLOOKUP(A9,'Invoice_Courier Company'!B:G,6,FALSE) -> Forward charges | E9: =IF(D9="Forward charges","Yes","No") -> Yes | F9: =IF(D9="Forward and RTO charges","Yes","No") -> No | G9: =SUMIFS('Order Report_Company X'!E:E,'Order Report_Company X'!A:A,A9)/1000 -> 1.168 | H9: =SUMIFS('Order Report_Company X'!E:E,'Order Report_Company X'!A:A,'Order Level Calculation_Company'!A9) -> 1168 | I9: {=_xlfn.IFS($G9<=0.5,0.5,$G9<=1,1,$G9<=1.5,1.5,$G9<=2,2,$G9<=2.5,2.5,$G9<=3,3,$G9<=3.5,3.5,$G9<=4,4)} -> 1.5 | J9: {=_xlfn.IFS($H9<=500,0.5,$H9<=1000,1,$H9<=1500,1.5,$H9<=2000,2,$H9<=2500,2.5,$H9<=3000,3,$H9<=3500,3.5,$H9<=4000,4)*1000} -> 1500 | K9: =UPPER(VLOOKUP(C9,'Zones Pincode_Company X'!B:C,2,FALSE)) -> B | L9: =VLOOKUP(K9,'Rates_Courier Company'!$B$7:$C$12,2,0) -> 33 | M9: =VLOOKUP(K9,'Rates_Courier Company'!$B$15:$C$20,2,FALSE)*(I9/0.5-1) -> 56.6 | N9: =IF(F9="Yes",VLOOKUP(K9,'Rates_Courier Company'!$F$7:$G$12,2,0),0) -> 0 | O9: =IF(F9="Yes",VLOOKUP(K9,'Rates_Courier Company'!$F$15:$G$20,2,0),0)*(I9/0.5 -1) -> 0 | P9: =L9+M9+N9+O9 -> 89.6 | Q9: =VLOOKUP(A9,'Invoice_Courier Company'!B:C,2,0) -> 1.15 | R9: =IF(Q9<=0.5,0.5,IF(AND(Q9>0.5,Q9<=1),1,IF(AND(Q9>1,Q9<=1.5),1.5,IF(AND(Q9>1.5,Q9<=2),2,IF(AND(Q9>2,Q9<=2.5),2.5,3))))) -> 1.5 | S9: =UPPER(VLOOKUP(A9,'Invoice_Courier Company'!B:G,5,FALSE)) -> B | T9: =VLOOKUP(A9,'Invoice_Courier Company'!B:H,7,0) -> 89.6 | U9: =P9-T9 -> 0 | V9: =U9/P9 -> 0 | W9: =L9+M9 -> 89.6 | X9: =N9+O9 -> 0
A10: 2001807186 | B10: 1091117323812 | C10: =VLOOKUP(A10,'Invoice_Courier Company'!B:E,4,FALSE) -> 396001 | D10: =VLOOKUP(A10,'Invoice_Courier Company'!B:G,6,FALSE) -> Forward charges | E10: =IF(D10="Forward charges","Yes","No") -> Yes | F10: =IF(D10="Forward and RTO charges","Yes","No") -> No | G10: =SUMIFS('Order Report_Company X'!E:E,'Order Report_Company X'!A:A,A10)/1000 -> 0.5 | H10: =SUMIFS('Order Report_Company X'!E:E,'Order Report_Company X'!A:A,'Order Level Calculation_Company'!A10) -> 500 | I10: {=_xlfn.IFS($G10<=0.5,0.5,$G10<=1,1,$G10<=1.5,1.5,$G10<=2,2,$G10<=2.5,2.5,$G10<=3,3,$G10<=3.5,3.5,$G10<=4,4)} -> 0.5 | J10: {=_xlfn.IFS($H10<=500,0.5,$H10<=1000,1,$H10<=1500,1.5,$H10<=2000,2,$H10<=2500,2.5,$H10<=3000,3,$H10<=3500,3.5,$H10<=4000,4)*1000} -> 500 | K10: =UPPER(VLOOKUP(C10,'Zones Pincode_Company X'!B:C,2,FALSE)) -> D | L10: =VLOOKUP(K10,'Rates_Courier Company'!$B$7:$C$12,2,0) -> 45.4 | M10: =VLOOKUP(K10,'Rates_Courier Company'!$B$15:$C$20,2,FALSE)*(I10/0.5-1) -> 0 | N10: =IF(F10="Yes",VLOOKUP(K10,'Rates_Courier Company'!$F$7:$G$12,2,0),0) -> 0 | O10: =IF(F10="Yes",VLOOKUP(K10,'Rates_Courier Company'!$F$15:$G$20,2,0),0)*(I10/0.5 -1) -> 0 | P10: =L10+M10+N10+O10 -> 45.4 | Q10: =VLOOKUP(A10,'Invoice_Courier Company'!B:C,2,0) -> 0.5 | R10: =IF(Q10<=0.5,0.5,IF(AND(Q10>0.5,Q10<=1),1,IF(AND(Q10>1,Q10<=1.5),1.5,IF(AND(Q10>1.5,Q10<=2),2,IF(AND(Q10>2,Q10<=2.5),2.5,3))))) -> 0.5 | S10: =UPPER(VLOOKUP(A10,'Invoice_Courier Company'!B:G,5,FALSE)) -> D | T10: =VLOOKUP(A10,'Invoice_Courier Company'!B:H,7,0) -> 45.4 | U10: =P10-T10 -> 0 | V10: =U10/P10 -> 0 | W10: =L10+M10 -> 45.4 | X10: =N10+O10 -> 0
A11: 2001807290 | B11: 1091117324206 | C11: =VLOOKUP(A11,'Invoice_Courier Company'!B:E,4,FALSE) -> 711106 | D11: =VLOOKUP(A11,'Invoice_Courier Company'!B:G,6,FALSE) -> Forward charges | E11: =IF(D11="Forward charges","Yes","No") -> Yes | F11: =IF(D11="Forward and RTO charges","Yes","No") -> No | G11: =SUMIFS('Order Report_Company X'!E:E,'Order Report_Company X'!A:A,A11)/1000 -> 0.5 | H11: =SUMIFS('Order Report_Company X'!E:E,'Order Report_Company X'!A:A,'Order Level Calculation_Company'!A11) -> 500 | I11: {=_xlfn.IFS($G11<=0.5,0.5,$G11<=1,1,$G11<=1.5,1.5,$G11<=2,2,$G11<=2.5,2.5,$G11<=3,3,$G11<=3.5,3.5,$G11<=4,4)} -> 0.5 | J11: {=_xlfn.IFS($H11<=500,0.5,$H11<=1000,1,$H11<=1500,1.5,$H11<=2000,2,$H11<=2500,2.5,$H11<=3000,3,$H11<=3500,3.5,$H11<=4000,4)*1000} -> 500 | K11: =UPPER(VLOOKUP(C11,'Zones Pincode_Company X'!B:C,2,FALSE)) -> D | L11: =VLOOKUP(K11,'Rates_Courier Company'!$B$7:$C$12,2,0) -> 45.4 | M11: =VLOOKUP(K11,'Rates_Courier Company'!$B$15:$C$20,2,FALSE)*(I11/0.5-1) -> 0 | N11: =IF(F11="Yes",VLOOKUP(K11,'Rates_Courier Company'!$F$7:$G$12,2,0),0) -> 0 | O11: =IF(F11="Yes",VLOOKUP(K11,'Rates_Courier Company'!$F$15:$G$20,2,0),0)*(I11/0.5 -1) -> 0 | P11: =L11+M11+N11+O11 -> 45.4 | Q11: =VLOOKUP(A11,'Invoice_Courier Company'!B:C,2,0) -> 0.5 | R11: =IF(Q11<=0.5,0.5,IF(AND(Q11>0.5,Q11<=1),1,IF(AND(Q11>1,Q11<=1.5),1.5,IF(AND(Q11>1.5,Q11<=2),2,IF(AND(Q11>2,Q11<=2.5),2.5,3))))) -> 0.5 | S11: =UPPER(VLOOKUP(A11,'Invoice_Courier Company'!B:G,5,FALSE)) -> D | T11: =VLOOKUP(A11,'Invoice_Courier Company'!B:H,7,0) -> 45.4 | U11: =P11-T11 -> 0 | V11: =U11/P11 -> 0 | W11: =L11+M11 -> 45.4 | X11: =N11+O11 -> 0
A12: 2001807814 | B12: 1091117326612 | C12: =VLOOKUP(A12,'Invoice_Courier Company'!B:E,4,FALSE) -> 284001 | D12: =VLOOKUP(A12,'Invoice_Courier Company'!B:G,6,FALSE) -> Forward charges | E12: =IF(D12="Forward charges","Yes","No") -> Yes | F12: =IF(D12="Forward and RTO charges","Yes","No") -> No | G12: =SUMIFS('Order Report_Company X'!E:E,'Order Report_Company X'!A:A,A12)/1000 -> 0.607 | H12: =SUMIFS('Order Report_Company X'!E:E,'Order Report_Company X'!A:A,'Order Level Calculation_Company'!A12) -> 607 | I12: {=_xlfn.IFS($G12<=0.5,0.5,$G12<=1,1,$G12<=1.5,1.5,$G12<=2,2,$G12<=2.5,2.5,$G12<=3,3,$G12<=3.5,3.5,$G12<=4,4)} -> 1 | J12: {=_xlfn.IFS($H12<=500,0.5,$H12<=1000,1,$H12<=1500,1.5,$H12<=2000,2,$H12<=2500,2.5,$H12<=3000,3,$H12<=3500,3.5,$H12<=4000,4)*1000} -> 1000 | K12: =UPPER(VLOOKUP(C12,'Zones Pincode_Company X'!B:C,2,FALSE)) -> B | L12: =VLOOKUP(K12,'Rates_Courier Company'!$B$7:$C$12,2,0) -> 33 | M12: =VLOOKUP(K12,'Rates_Courier Company'!$B$15:$C$20,2,FALSE)*(I12/0.5-1) -> 28.3 | N12: =IF(F12="Yes",VLOOKUP(K12,'Rates_Courier Company'!$F$7:$G$12,2,0),0) -> 0 | O12: =IF(F12="Yes",VLOOKUP(K12,'Rates_Courier Company'!$F$15:$G$20,2,0),0)*(I12/0.5 -1) -> 0 | P12: =L12+M12+N12+O12 -> 61.3 | Q12: =VLOOKUP(A12,'Invoice_Courier Company'!B:C,2,0) -> 0.79 | R12: =IF(Q12<=0.5,0.5,IF(AND(Q12>0.5,Q12<=1),1,IF(AND(Q12>1,Q12<=1.5),1.5,IF(AND(Q12>1.5,Q12<=2),2,IF(AND(Q12>2,Q12<=2.5),2.5,3))))) -> 1 | S12: =UPPER(VLOOKUP(A12,'Invoice_Courier Company'!B:G,5,FALSE)) -> B | T12: =VLOOKUP(A12,'Invoice_Courier Company'!B:H,7,0) -> 61.3 | U12: =P12-T12 -> 0 | V12: =U12/P12 -> 0 | W12: =L12+M12 -> 61.3 | X12: =N12+O12 -> 0
A13: 2001807931 | B13: 1091117327172 | C13: =VLOOKUP(A13,'Invoice_Courier Company'!B:E,4,FALSE) -> 441601 | D13: =VLOOKUP(A13,'Invoice_Courier Company'!B:G,6,FALSE) -> Forward charges | E13: =IF(D13="Forward charges","Yes","No") -> Yes | F13: =IF(D13="Forward and RTO charges","Yes","No") -> No | G13: =SUMIFS('Order Report_Company X'!E:E,'Order Report_Company X'!A:A,A13)/1000 -> 0.607 | H13: =SUMIFS('Order Report_Company X'!E:E,'Order Report_Company X'!A:A,'Order Level Calculation_Company'!A13) -> 607 | I13: {=_xlfn.IFS($G13<=0.5,0.5,$G13<=1,1,$G13<=1.5,1.5,$G13<=2,2,$G13<=2.5,2.5,$G13<=3,3,$G13<=3.5,3.5,$G13<=4,4)} -> 1 | J13: {=_xlfn.IFS($H13<=500,0.5,$H13<=1000,1,$H13<=1500,1.5,$H13<=2000,2,$H13<=2500,2.5,$H13<=3000,3,$H13<=3500,3.5,$H13<=4000,4)*1000} -> 1000 | K13: =UPPER(VLOOKUP(C13,'Zones Pincode_Company X'!B:C,2,FALSE)) -> D | L13: =VLOOKUP(K13,'Rates_Courier Company'!$B$7:$C$12,2,0) -> 45.4 | M13: =VLOOKUP(K13,'Rates_Courier Company'!$B$15:$C$20,2,FALSE)*(I13/0.5-1) -> 44.8 | N13: =IF(F13="Yes",VLOOKUP(K13,'Rates_Courier Company'!$F$7:$G$12,2,0),0) -> 0 | O13: =IF(F13="Yes",VLOOKUP(K13,'Rates_Courier Company'!$F$15:$G$20,2,0),0)*(I13/0.5 -1) -> 0 | P13: =L13+M13+N13+O13 -> 90.2 | Q13: =VLOOKUP(A13,'Invoice_Courier Company'!B:C,2,0) -> 0.72 | R13: =IF(Q13<=0.5,0.5,IF(AND(Q13>0.5,Q13<=1),1,IF(AND(Q13>1,Q13<=1.5),1.5,IF(AND(Q13>1.5,Q13<=2),2,IF(AND(Q13>2,Q13<=2.5),2.5,3))))) -> 1 | S13: =UPPER(VLOOKUP(A13,'Invoice_Courier Company'!B:G,5,FALSE)) -> D | T13: =VLOOKUP(A13,'Invoice_Courier Company'!B:H,7,0) -> 90.2 | U13: =P13-T13 -> 0 | V13: =U13/P13 -> 0 | W13: =L13+M13 -> 90.2 | X13: =N13+O13 -> 0
A14: 2001807956 | B14: 1091117327275 | C14: =VLOOKUP(A14,'Invoice_Courier Company'!B:E,4,FALSE) -> 248006 | D14: =VLOOKUP(A14,'Invoice_Courier Company'!B:G,6,FALSE) -> Forward charges | E14: =IF(D14="Forward charges","Yes","No") -> Yes | F14: =IF(D14="Forward and RTO charges","Yes","No") -> No | G14: =SUMIFS('Order Report_Company X'!E:E,'Order Report_Company X'!A:A,A14)/1000 -> 1.08 | H14: =SUMIFS('Order Report_Company X'!E:E,'Order Report_Company X'!A:A,'Order Level Calculation_Company'!A14) -> 1080 | I14: {=_xlfn.IFS($G14<=0.5,0.5,$G14<=1,1,$G14<=1.5,1.5,$G14<=2,2,$G14<=2.5,2.5,$G14<=3,3,$G14<=3.5,3.5,$G14<=4,4)} -> 1.5 | J14: {=_xlfn.IFS($H14<=500,0.5,$H14<=1000,1,$H14<=1500,1.5,$H14<=2000,2,$H14<=2500,2.5,$H14<=3000,3,$H14<=3500,3.5,$H14<=4000,4)*1000} -> 1500 | K14: =UPPER(VLOOKUP(C14,'Zones Pincode_Company X'!B:C,2,FALSE)) -> B | L14: =VLOOKUP(K14,'Rates_Courier Company'!$B$7:$C$12,2,0) -> 33 | M14: =VLOOKUP(K14,'Rates_Courier Company'!$B$15:$C$20,2,FALSE)*(I14/0.5-1) -> 56.6 | N14: =IF(F14="Yes",VLOOKUP(K14,'Rates_Courier Company'!$F$7:$G$12,2,0),0) -> 0 | O14: =IF(F14="Yes",VLOOKUP(K14,'Rates_Courier Company'!$F$15:$G$20,2,0),0)*(I14/0.5 -1) -> 0 | P14: =L14+M14+N14+O14 -> 89.6 | Q14: =VLOOKUP(A14,'Invoice_Courier Company'!B:C,2,0) -> 1.08 | R14: =IF(Q14<=0.5,0.5,IF(AND(Q14>0.5,Q14<=1),1,IF(AND(Q14>1,Q14<=1.5),1.5,IF(AND(Q14>1.5,Q14<=2),2,IF(AND(Q14>2,Q14<=2.5),2.5,3))))) -> 1.5 | S14: =UPPER(VLOOKUP(A14,'Invoice_Courier Company'!B:G,5,FALSE)) -> B | T14: =VLOOKUP(A14,'Invoice_Courier Company'!B:H,7,0) -> 89.6 | U14: =P14-T14 -> 0 | V14: =U14/P14 -> 0 | W14: =L14+M14 -> 89.6 | X14: =N14+O14 -> 0
... A125: 2001811305 | B125: 1091121846136 | C125: =VLOOKUP(A125,'Invoice_Courier Company'!B:E,4,FALSE) -> 302020 | D125: =VLOOKUP(A125,'Invoice_Courier Company'!B:G,6,FALSE) -> Forward charges | E125: =IF(D125="Forward charges","Yes","No") -> Yes | F125: =IF(D125="Forward and RTO charges","Yes","No") -> No | G125: =SUMIFS('Order Report_Company X'!E:E,'Order Report_Company X'!A:A,A125)/1000 -> 0.75 | H125: =SUMIFS('Order Report_Company X'!E:E,'Order Report_Company X'!A:A,'Order Level Calculation_Company'!A125) -> 750 | I125: {=_xlfn.IFS($G125<=0.5,0.5,$G125<=1,1,$G125<=1.5,1.5,$G125<=2,2,$G125<=2.5,2.5,$G125<=3,3,$G125<=3.5,3.5,$G125<=4,4)} -> 1 | J125: {=_xlfn.IFS($H125<=500,0.5,$H125<=1000,1,$H125<=1500,1.5,$H125<=2000,2,$H125<=2500,2.5,$H125<=3000,3,$H125<=3500,3.5,$H125<=4000,4)*1000} -> 1000 | K125: =UPPER(VLOOKUP(C125,'Zones Pincode_Company X'!B:C,2,FALSE)) -> B | L125: =VLOOKUP(K125,'Rates_Courier Company'!$B$7:$C$12,2,0) -> 33 | M125: =VLOOKUP(K125,'Rates_Courier Company'!$B$15:$C$20,2,FALSE)*(I125/0.5-1) -> 28.3 | N125: =IF(F125="Yes",VLOOKUP(K125,'Rates_Courier Company'!$F$7:$G$12,2,0),0) -> 0 | O125: =IF(F125="Yes",VLOOKUP(K125,'Rates_Courier Company'!$F$15:$G$20,2,0),0)*(I125/0.5 -1) -> 0 | P125: =L125+M125+N125+O125 -> 61.3 | Q125: =VLOOKUP(A125,'Invoice_Courier Company'!B:C,2,0) -> 0.5 | R125: =IF(Q125<=0.5,0.5,IF(AND(Q125>0.5,Q125<=1),1,IF(AND(Q125>1,Q125<=1.5),1.5,IF(AND(Q125>1.5,Q125<=2),2,IF(AND(Q125>2,Q125<=2.5),2.5,3))))) -> 0.5 | S125: =UPPER(VLOOKUP(A125,'Invoice_Courier Company'!B:G,5,FALSE)) -> D | T125: =VLOOKUP(A125,'Invoice_Courier Company'!B:H,7,0) -> 45.4 | U125: =P125-T125 -> 15.9 | V125: =U125/P125 -> 0.2593801 | W125: =L125+M125 -> 61.3 | X125: =N125+O125 -> 0
